2022-04-17 21:51:16.054 | DEBUG    | aria2p.interface:run:504 - Created new screen <tests.test_interface.MockedScreen object at 0x7f961430bfd0>
2022-04-17 21:51:16.055 | ERROR    | aria2p.interface:run:559 - some message
Traceback (most recent call last):

  File "<string>", line 1, in <module>
  File "<string>", line 8, in <module>
  File "/media/data/dev/aria2p/__pypackages__/3.11/lib/execnet/gateway_base.py", line 1554, in serve
    WorkerGateway(io=io, id=id, _startcount=2).serve()
    │                │      └ 'gw1-worker'
    │                └ <execnet.gateway_base.Popen2IO object at 0x7f961879ea90>
    └ <class 'execnet.gateway_base.WorkerGateway'>
  File "/media/data/dev/aria2p/__pypackages__/3.11/lib/execnet/gateway_base.py", line 1060, in serve
    self._execpool.integrate_as_primary_thread()
    │    │         └ <function WorkerPool.integrate_as_primary_thread at 0x7f96188e7ce0>
    │    └ <execnet.gateway_base.WorkerPool object at 0x7f96187bd6d0>
    └ <execnet.gateway_base.WorkerGateway object at 0x7f96187bd3d0>
  File "/media/data/dev/aria2p/__pypackages__/3.11/lib/execnet/gateway_base.py", line 267, in integrate_as_primary_thread
    self._perform_spawn(reply)
    │    │              └ <execnet.gateway_base.Reply object at 0x7f96187bde50>
    │    └ <function WorkerPool._perform_spawn at 0x7f96188e7ec0>
    └ <execnet.gateway_base.WorkerPool object at 0x7f96187bd6d0>
  File "/media/data/dev/aria2p/__pypackages__/3.11/lib/execnet/gateway_base.py", line 285, in _perform_spawn
    reply.run()
    │     └ <function Reply.run at 0x7f96188e7ba0>
    └ <execnet.gateway_base.Reply object at 0x7f96187bde50>
  File "/media/data/dev/aria2p/__pypackages__/3.11/lib/execnet/gateway_base.py", line 220, in run
    self._result = func(*args, **kwargs)
    │              │     │       └ {}
    │              │     └ ((<Channel id=1 open>, ('"""\n    This module is executed in remote subprocesses and helps to\n    control a remote testing s...
    │              └ <bound method WorkerGateway.executetask of <execnet.gateway_base.WorkerGateway object at 0x7f96187bd3d0>>
    └ <execnet.gateway_base.Reply object at 0x7f96187bde50>
  File "/media/data/dev/aria2p/__pypackages__/3.11/lib/execnet/gateway_base.py", line 1084, in executetask
    do_exec(co, loc)  # noqa
    │       │   └ {'channel': <Channel id=1 open>, '__name__': '__channelexec__', '__builtins__': {'__name__': 'builtins', '__doc__': "Built-in...
    │       └ <code object <module> at 0x7f96187c1290, file "/media/data/dev/aria2p/__pypackages__/3.11/lib/xdist/remote.py", line 1>
    └ <built-in function exec>
  File "/media/data/dev/aria2p/__pypackages__/3.11/lib/xdist/remote.py", line 291, in <module>
    config.hook.pytest_cmdline_main(config=config)
    │      │    │                          └ <_pytest.config.Config object at 0x7f961719ffd0>
    │      │    └ <_HookCaller 'pytest_cmdline_main'>
    │      └ <pluggy._hooks._HookRelay object at 0x7f961719f150>
    └ <_pytest.config.Config object at 0x7f961719ffd0>
  File "/media/data/dev/aria2p/__pypackages__/3.11/lib/pluggy/_hooks.py", line 265, in __call__
    return self._hookexec(self.name, self.get_hookimpls(), kwargs, firstresult)
           │    │         │    │     │    │                │       └ True
           │    │         │    │     │    │                └ {'config': <_pytest.config.Config object at 0x7f961719ffd0>}
           │    │         │    │     │    └ <function _HookCaller.get_hookimpls at 0x7f9617748b80>
           │    │         │    │     └ <_HookCaller 'pytest_cmdline_main'>
           │    │         │    └ 'pytest_cmdline_main'
           │    │         └ <_HookCaller 'pytest_cmdline_main'>
           │    └ <bound method PluginManager._hookexec of <_pytest.config.PytestPluginManager object at 0x7f961719efd0>>
           └ <_HookCaller 'pytest_cmdline_main'>
  File "/media/data/dev/aria2p/__pypackages__/3.11/lib/pluggy/_manager.py", line 80, in _hookexec
    return self._inner_hookexec(hook_name, methods, kwargs, firstresult)
           │    │               │          │        │       └ True
           │    │               │          │        └ {'config': <_pytest.config.Config object at 0x7f961719ffd0>}
           │    │               │          └ [<HookImpl plugin_name='main', plugin=<module '_pytest.main' from '/media/data/dev/aria2p/__pypackages__/3.11/lib/_pytest/mai...
           │    │               └ 'pytest_cmdline_main'
           │    └ <function _multicall at 0x7f9617703ba0>
           └ <_pytest.config.PytestPluginManager object at 0x7f961719efd0>
  File "/media/data/dev/aria2p/__pypackages__/3.11/lib/pluggy/_callers.py", line 39, in _multicall
    res = hook_impl.function(*args)
          │         │         └ [<_pytest.config.Config object at 0x7f961719ffd0>]
          │         └ <function pytest_cmdline_main at 0x7f9617401940>
          └ <HookImpl plugin_name='main', plugin=<module '_pytest.main' from '/media/data/dev/aria2p/__pypackages__/3.11/lib/_pytest/main...
  File "/media/data/dev/aria2p/__pypackages__/3.11/lib/_pytest/main.py", line 316, in pytest_cmdline_main
    return wrap_session(config, _main)
           │            │       └ <function _main at 0x7f96174019e0>
           │            └ <_pytest.config.Config object at 0x7f961719ffd0>
           └ <function wrap_session at 0x7f96174018a0>
  File "/media/data/dev/aria2p/__pypackages__/3.11/lib/_pytest/main.py", line 269, in wrap_session
    session.exitstatus = doit(config, session) or 0
    │       │            │    │       └ <Session tests exitstatus=<ExitCode.OK: 0> testsfailed=1 testscollected=480>
    │       │            │    └ <_pytest.config.Config object at 0x7f961719ffd0>
    │       │            └ <function _main at 0x7f96174019e0>
    │       └ <ExitCode.OK: 0>
    └ <Session tests exitstatus=<ExitCode.OK: 0> testsfailed=1 testscollected=480>
  File "/media/data/dev/aria2p/__pypackages__/3.11/lib/_pytest/main.py", line 323, in _main
    config.hook.pytest_runtestloop(session=session)
    │      │    │                          └ <Session tests exitstatus=<ExitCode.OK: 0> testsfailed=1 testscollected=480>
    │      │    └ <_HookCaller 'pytest_runtestloop'>
    │      └ <pluggy._hooks._HookRelay object at 0x7f961719f150>
    └ <_pytest.config.Config object at 0x7f961719ffd0>
  File "/media/data/dev/aria2p/__pypackages__/3.11/lib/pluggy/_hooks.py", line 265, in __call__
    return self._hookexec(self.name, self.get_hookimpls(), kwargs, firstresult)
           │    │         │    │     │    │                │       └ True
           │    │         │    │     │    │                └ {'session': <Session tests exitstatus=<ExitCode.OK: 0> testsfailed=1 testscollected=480>}
           │    │         │    │     │    └ <function _HookCaller.get_hookimpls at 0x7f9617748b80>
           │    │         │    │     └ <_HookCaller 'pytest_runtestloop'>
           │    │         │    └ 'pytest_runtestloop'
           │    │         └ <_HookCaller 'pytest_runtestloop'>
           │    └ <bound method PluginManager._hookexec of <_pytest.config.PytestPluginManager object at 0x7f961719efd0>>
           └ <_HookCaller 'pytest_runtestloop'>
  File "/media/data/dev/aria2p/__pypackages__/3.11/lib/pluggy/_manager.py", line 80, in _hookexec
    return self._inner_hookexec(hook_name, methods, kwargs, firstresult)
           │    │               │          │        │       └ True
           │    │               │          │        └ {'session': <Session tests exitstatus=<ExitCode.OK: 0> testsfailed=1 testscollected=480>}
           │    │               │          └ [<HookImpl plugin_name='main', plugin=<module '_pytest.main' from '/media/data/dev/aria2p/__pypackages__/3.11/lib/_pytest/mai...
           │    │               └ 'pytest_runtestloop'
           │    └ <function _multicall at 0x7f9617703ba0>
           └ <_pytest.config.PytestPluginManager object at 0x7f961719efd0>
  File "/media/data/dev/aria2p/__pypackages__/3.11/lib/pluggy/_callers.py", line 39, in _multicall
    res = hook_impl.function(*args)
          │         │         └ [<Session tests exitstatus=<ExitCode.OK: 0> testsfailed=1 testscollected=480>]
          │         └ <bound method WorkerInteractor.pytest_runtestloop of <__channelexec__.WorkerInteractor object at 0x7f9616f88310>>
          └ <HookImpl plugin_name='140282607207184', plugin=<__channelexec__.WorkerInteractor object at 0x7f9616f88310>>
  File "/media/data/dev/aria2p/__pypackages__/3.11/lib/xdist/remote.py", line 91, in pytest_runtestloop
    self.run_one_test(torun)
    │    │            └ [258, 259]
    │    └ <function WorkerInteractor.run_one_test at 0x7f961719bf60>
    └ <__channelexec__.WorkerInteractor object at 0x7f9616f88310>
  File "/media/data/dev/aria2p/__pypackages__/3.11/lib/xdist/remote.py", line 110, in run_one_test
    self.config.hook.pytest_runtest_protocol(item=item, nextitem=nextitem)
    │    │      │    │                            │              └ <Function test_remember_last_remove>
    │    │      │    │                            └ <Function test_log_exception>
    │    │      │    └ <_HookCaller 'pytest_runtest_protocol'>
    │    │      └ <pluggy._hooks._HookRelay object at 0x7f961719f150>
    │    └ <_pytest.config.Config object at 0x7f961719ffd0>
    └ <__channelexec__.WorkerInteractor object at 0x7f9616f88310>
  File "/media/data/dev/aria2p/__pypackages__/3.11/lib/pluggy/_hooks.py", line 265, in __call__
    return self._hookexec(self.name, self.get_hookimpls(), kwargs, firstresult)
           │    │         │    │     │    │                │       └ True
           │    │         │    │     │    │                └ {'item': <Function test_log_exception>, 'nextitem': <Function test_remember_last_remove>}
           │    │         │    │     │    └ <function _HookCaller.get_hookimpls at 0x7f9617748b80>
           │    │         │    │     └ <_HookCaller 'pytest_runtest_protocol'>
           │    │         │    └ 'pytest_runtest_protocol'
           │    │         └ <_HookCaller 'pytest_runtest_protocol'>
           │    └ <bound method PluginManager._hookexec of <_pytest.config.PytestPluginManager object at 0x7f961719efd0>>
           └ <_HookCaller 'pytest_runtest_protocol'>
  File "/media/data/dev/aria2p/__pypackages__/3.11/lib/pluggy/_manager.py", line 80, in _hookexec
    return self._inner_hookexec(hook_name, methods, kwargs, firstresult)
           │    │               │          │        │       └ True
           │    │               │          │        └ {'item': <Function test_log_exception>, 'nextitem': <Function test_remember_last_remove>}
           │    │               │          └ [<HookImpl plugin_name='runner', plugin=<module '_pytest.runner' from '/media/data/dev/aria2p/__pypackages__/3.11/lib/_pytest...
           │    │               └ 'pytest_runtest_protocol'
           │    └ <function _multicall at 0x7f9617703ba0>
           └ <_pytest.config.PytestPluginManager object at 0x7f961719efd0>
  File "/media/data/dev/aria2p/__pypackages__/3.11/lib/pluggy/_callers.py", line 39, in _multicall
    res = hook_impl.function(*args)
          │         │         └ [<Function test_log_exception>, <Function test_remember_last_remove>]
          │         └ <function pytest_runtest_protocol at 0x7f9616c3cf40>
          └ <HookImpl plugin_name='rerunfailures', plugin=<module 'pytest_rerunfailures' from '/media/data/dev/aria2p/__pypackages__/3.11...
  File "/media/data/dev/aria2p/__pypackages__/3.11/lib/pytest_rerunfailures.py", line 240, in pytest_runtest_protocol
    reports = runtestprotocol(item, nextitem=nextitem, log=False)
              │               │              └ <Function test_remember_last_remove>
              │               └ <Function test_log_exception>
              └ <function runtestprotocol at 0x7f96173e3f60>
  File "/media/data/dev/aria2p/__pypackages__/3.11/lib/_pytest/runner.py", line 126, in runtestprotocol
    reports.append(call_and_report(item, "call", log))
    │       │      │               │             └ False
    │       │      │               └ <Function test_log_exception>
    │       │      └ <function call_and_report at 0x7f9617400360>
    │       └ <method 'append' of 'list' objects>
    └ [<TestReport 'test_interface.py::test_log_exception' when='setup' outcome='passed'>]
  File "/media/data/dev/aria2p/__pypackages__/3.11/lib/_pytest/runner.py", line 215, in call_and_report
    call = call_runtest_hook(item, when, **kwds)
           │                 │     │       └ {}
           │                 │     └ 'call'
           │                 └ <Function test_log_exception>
           └ <function call_runtest_hook at 0x7f9617400540>
  File "/media/data/dev/aria2p/__pypackages__/3.11/lib/_pytest/runner.py", line 254, in call_runtest_hook
    return CallInfo.from_call(
           │        └ <classmethod(<function CallInfo.from_call at 0x7f9617400b80>)>
           └ <class '_pytest.runner.CallInfo'>
  File "/media/data/dev/aria2p/__pypackages__/3.11/lib/_pytest/runner.py", line 311, in from_call
    result: Optional[TResult] = func()
            │        │          └ <function call_runtest_hook.<locals>.<lambda> at 0x7f961413b920>
            │        └ +TResult
            └ typing.Optional
  File "/media/data/dev/aria2p/__pypackages__/3.11/lib/_pytest/runner.py", line 255, in <lambda>
    lambda: ihook(item=item, **kwds), when=when, reraise=reraise
            │          │       └ {}
            │          └ <Function test_log_exception>
            └ <_HookCaller 'pytest_runtest_call'>
  File "/media/data/dev/aria2p/__pypackages__/3.11/lib/pluggy/_hooks.py", line 265, in __call__
    return self._hookexec(self.name, self.get_hookimpls(), kwargs, firstresult)
           │    │         │    │     │    │                │       └ False
           │    │         │    │     │    │                └ {'item': <Function test_log_exception>}
           │    │         │    │     │    └ <function _HookCaller.get_hookimpls at 0x7f9617748b80>
           │    │         │    │     └ <_HookCaller 'pytest_runtest_call'>
           │    │         │    └ 'pytest_runtest_call'
           │    │         └ <_HookCaller 'pytest_runtest_call'>
           │    └ <bound method PluginManager._hookexec of <_pytest.config.PytestPluginManager object at 0x7f961719efd0>>
           └ <_HookCaller 'pytest_runtest_call'>
  File "/media/data/dev/aria2p/__pypackages__/3.11/lib/pluggy/_manager.py", line 80, in _hookexec
    return self._inner_hookexec(hook_name, methods, kwargs, firstresult)
           │    │               │          │        │       └ False
           │    │               │          │        └ {'item': <Function test_log_exception>}
           │    │               │          └ [<HookImpl plugin_name='runner', plugin=<module '_pytest.runner' from '/media/data/dev/aria2p/__pypackages__/3.11/lib/_pytest...
           │    │               └ 'pytest_runtest_call'
           │    └ <function _multicall at 0x7f9617703ba0>
           └ <_pytest.config.PytestPluginManager object at 0x7f961719efd0>
  File "/media/data/dev/aria2p/__pypackages__/3.11/lib/pluggy/_callers.py", line 39, in _multicall
    res = hook_impl.function(*args)
          │         │         └ [<Function test_log_exception>]
          │         └ <function pytest_runtest_call at 0x7f9617400180>
          └ <HookImpl plugin_name='runner', plugin=<module '_pytest.runner' from '/media/data/dev/aria2p/__pypackages__/3.11/lib/_pytest/...
  File "/media/data/dev/aria2p/__pypackages__/3.11/lib/_pytest/runner.py", line 162, in pytest_runtest_call
    item.runtest()
    │    └ <function Function.runtest at 0x7f9617453560>
    └ <Function test_log_exception>
  File "/media/data/dev/aria2p/__pypackages__/3.11/lib/_pytest/python.py", line 1641, in runtest
    self.ihook.pytest_pyfunc_call(pyfuncitem=self)
    │    │                                   └ <Function test_log_exception>
    │    └ <property object at 0x7f9617537b00>
    └ <Function test_log_exception>
  File "/media/data/dev/aria2p/__pypackages__/3.11/lib/pluggy/_hooks.py", line 265, in __call__
    return self._hookexec(self.name, self.get_hookimpls(), kwargs, firstresult)
           │    │         │    │     │    │                │       └ True
           │    │         │    │     │    │                └ {'pyfuncitem': <Function test_log_exception>}
           │    │         │    │     │    └ <function _HookCaller.get_hookimpls at 0x7f9617748b80>
           │    │         │    │     └ <_HookCaller 'pytest_pyfunc_call'>
           │    │         │    └ 'pytest_pyfunc_call'
           │    │         └ <_HookCaller 'pytest_pyfunc_call'>
           │    └ <bound method PluginManager._hookexec of <_pytest.config.PytestPluginManager object at 0x7f961719efd0>>
           └ <_HookCaller 'pytest_pyfunc_call'>
  File "/media/data/dev/aria2p/__pypackages__/3.11/lib/pluggy/_manager.py", line 80, in _hookexec
    return self._inner_hookexec(hook_name, methods, kwargs, firstresult)
           │    │               │          │        │       └ True
           │    │               │          │        └ {'pyfuncitem': <Function test_log_exception>}
           │    │               │          └ [<HookImpl plugin_name='python', plugin=<module '_pytest.python' from '/media/data/dev/aria2p/__pypackages__/3.11/lib/_pytest...
           │    │               └ 'pytest_pyfunc_call'
           │    └ <function _multicall at 0x7f9617703ba0>
           └ <_pytest.config.PytestPluginManager object at 0x7f961719efd0>
  File "/media/data/dev/aria2p/__pypackages__/3.11/lib/pluggy/_callers.py", line 39, in _multicall
    res = hook_impl.function(*args)
          │         │         └ [<Function test_log_exception>]
          │         └ <function pytest_pyfunc_call at 0x7f9617450360>
          └ <HookImpl plugin_name='python', plugin=<module '_pytest.python' from '/media/data/dev/aria2p/__pypackages__/3.11/lib/_pytest/...
  File "/media/data/dev/aria2p/__pypackages__/3.11/lib/_pytest/python.py", line 183, in pytest_pyfunc_call
    result = testfunction(**testargs)
             │              └ {'tmp_path': PosixPath('/tmp/pytest-of-pawamoy/pytest-4/popen-gw1/test_log_exception0'), 'port': 15350, 'monkeypatch': <_pyte...
             └ <function test_log_exception at 0x7f9614b98040>

  File "/media/data/dev/aria2p/tests/test_interface.py", line 224, in test_log_exception
    assert not interface.run()
               │         └ <function Interface.run at 0x7f9615bda840>
               └ <aria2p.interface.Interface object at 0x7f96142f1d10>

> File "/media/data/dev/aria2p/src/aria2p/interface.py", line 518, in run
    event = screen.get_event()
            │      └ <function MockedScreen.get_event at 0x7f9614bb3a60>
            └ <tests.test_interface.MockedScreen object at 0x7f961430bfd0>

  File "/media/data/dev/aria2p/tests/test_interface.py", line 141, in get_event
    raise event.value
          │     └ LookupError('some message')
          └ <tests.test_interface.SpecialEvent object at 0x7f96142ff750>

LookupError: some message
